Workbook

Sheet Participantes - Banquito
A1: Nombre | B1: Diciembre | C1: Enero | D1: Febrero | E1: Marzo | F1: Abril | G1: Mayo | H1: Junio | I1: Julio | J1: Agosto | K1: Setiembre | L1: Octubre | M1: Noviembre | N1: Diciembre
A2: Sonia Silva | B2: 1 | C2: 1 | D2: 1 | E2: 1 | F2: 1 | G2: 1 | H2: 1 | I2: 1 | J2: 1 | K2: 1 | L2: 1 | M2: 1 | N2: 1
A3: Jhary Bravo | B3: 1 | C3: 1 | D3: 1 | E3: 1 | F3: 1 | G3: 1 | H3: 1 | I3: 1 | J3: 1 | K3: 1 | L3: 1 | M3: 1 | N3: 1
A4: Jennifer Nuñez | B4: 1 | C4: 1 | D4: 1 | E4: 1 | F4: 1 | G4: 1 | H4: 1 | I4: 1 | J4: 1 | K4: 1 | L4: 1 | M4: 1 | N4: 1
A5: Marco Gutierres | B5: 1 | C5: 1 | D5: 1 | E5: 1 | F5: 1 | G5: 1 | H5: 1 | I5: 1 | J5: 1 | K5: 1 | L5: 1 | M5: 1 | N5: 1
A6: Kelly Gonzales | B6: 1 | C6: 1 | D6: 1 | E6: 1 | F6: 1 | G6: 1 | H6: 1 | I6: 1 | J6: 1 | K6: 1 | L6: 1 | M6: 1 | N6: 1
A7: Estefanny Silva | B7: 1 | C7: 2 | D7: 2 | E7: 2 | F7: 2 | G7: 2 | H7: 2 | I7: 2 | J7: 2 | K7: 2 | L7: 2 | M7: 2 | N7: 2
A8: Haytza Silva | B8: 1 | C8: 1 | D8: 1 | E8: 1 | F8: 1 | G8: 1 | H8: 1 | I8: 1 | J8: 1 | K8: 1 | L8: 1 | M8: 1 | N8: 1
A9: Medelein Poma | B9: 1 | C9: 1 | D9: 1 | E9: 1 | F9: 1 | G9: 1 | H9: 1 | I9: 1 | J9: 1 | K9: 1 | L9: 1 | M9: 1 | N9: 1
A10: Chela Silva | B10: 1 | C10: 1 | D10: 1 | E10: 1 | F10: 1 | G10: 1 | H10: 1 | I10: 1 | J10: 1 | K10: 1 | L10: 1 | M10: 1 | N10: 1
A11: Cledmir Tejada | B11: 2 | C11: 2 | D11: 2 | E11: 2 | F11: 2 | G11: 2 | H11: 2 | I11: 2 | J11: 2 | K11: 2 | L11: 2 | M11: 2 | N11: 2
A12: Omar Goicochea | B12: 1 | C12: 1 | D12: 1 | E12: 1 | F12: 1 | G12: 1 | H12: 1 | I12: 1 | J12: 1 | K12: 1 | L12: 1 | M12: 1 | N12: 1
A13: Adriana Gutierrez | B13: 1 | C13: 1 | D13: 1 | E13: 1 | F13: 1 | G13: 1 | H13: 1 | I13: 1 | J13: 1 | K13: 1 | L13: 1 | M13: 1 | N13: 1
A14: Nora Silva | B14: 0 | C14: 1 | D14: 1 | E14: 1 | F14: 1 | G14: 1 | H14: 1 | I14: 1 | J14: 1 | K14: 1 | L14: 1 | M14: 1 | N14: 1
A15: Total | B15: =100*(SUM(B2:B14)) -> 1300 | C15: =100*(SUM(C2:C14)) -> 1500 | D15: =100*(SUM(D2:D14)) -> 1500 | E15: =100*(SUM(E2:E14)) -> 1500 | F15: =100*(SUM(F2:F14)) -> 1500 | G15: =100*(SUM(G2:G14)) -> 1500 | H15: =100*(SUM(H2:H14)) -> 1500 | I15: =100*(SUM(I2:I14)) -> 1500 | ... N15: =100*(SUM(N2:N14)) -> 1500

Sheet Flujo de Caja - Banquito
A2: Nombre | B2: Monto Pestado | C2: N° Cuotas | D2: Diciembre | E2: Enero | F2: Febrero | G2: Marzo | H2: Abril | I2: Mayo | J2: Junio | K2: Julio | L2: Agosto | M2: Setiembre | N2: Octubre | O2: Noviembre | P2: Diciembre | Q2: Monto Total Pagado | R2: Intereses Generados
A3: Madhelein | B3: 1300 | C3: 12 | E3: 146.7 | F3: 146.7 | G3: 146.7 | H3: 146.7 | I3: 146.7 | J3: 146.7 | K3: 146.7 | L3: 146.7 | M3: 146.7 | N3: 146.7 | O3: 146.7 | P3: 146.7 | Q3: =SUM(D3:P3) -> 1760.4 | R3: =Q3-B3 -> 460.4
A4: Marco | B4: 1856.7 | C4: 11 | F4: 223.5 | G4: 223.5 | H4: 223.5 | I4: 223.5 | J4: 223.5 | K4: 223.5 | L4: 223.5 | M4: 223.5 | N4: 223.5 | O4: 223.5 | P4: 223.5 | Q4: =SUM(D4:P4) -> 2458.5 | R4: =Q4-B4 -> 601.8
A5: Jennifer | B5: 1870.2 | C5: 7 | G5: 323.2 | H5: 323.2 | I5: 323.2 | J5: 323.2 | K5: 323.2 | L5: 323.2 | M5: 323.2 | Q5: =SUM(D5:P5) -> 2262.4 | R5: =Q5-B5 -> 392.2
A6: Jhary | B6: 2193.5 | C6: 4 | H6: 618.6 | I6: 618.6 | J6: 618.6 | K6: 618.6 | Q6: =SUM(D6:P6) -> 2474.4 | R6: =Q6-B6 -> 280.9
A7: Nora | B7: 2812.1 | C7: 7 | I7: 486 | J7: 486 | K7: 486 | L7: 486 | M7: 486 | N7: 486 | O7: 486 | Q7: =SUM(D7:P7) -> 3402 | R7: =Q7-B7 -> 589.9
A8: Estafany | B8: 3298.1 | C8: 7 | J8: 570 | K8: 570 | L8: 570 | M8: 570 | N8: 570 | O8: 570 | P8: 570 | Q8: =SUM(D8:P8) -> 3990 | R8: =Q8-B8 -> 691.9
A9: Omar Goicochea | B9: 3868.1 | C9: 6 | K9: 762.1 | L9: 762.1 | M9: 762.1 | Q9: =SUM(D9:P9)+M33 -> 4361.6 | R9: =Q9-B9 -> 493.5
A10: Adriana Gutierrez | B10: 4630.1 | C10: 5 | L10: 1069.4 | M10: 1069.4 | N10: 1069.4 | O10: 1069.4 | P10: 1069.4 | Q10: =SUM(D10:P10) -> 5347 | R10: =Q10-B10 -> 716.9
A11: Estefanny Silva | B11: 3580.9 | C11: 4 | M11: 1009.9 | N11: 1009.9 | O11: 1009.9 | P11: 1009.9 | Q11: =SUM(D11:P11) -> 4039.6 | R11: =Q11-B11 -> 458.7
A12: Jhary Bravo | B12: 1500 | C12: 4 | M12: 423 | N12: 423 | O12: 423 | P12: 423 | Q12: =SUM(D12:P12) -> 1692 | R12: =Q12-B12 -> 192
A13: Omar Goicochea | B13: 7000 | C13: 3 | N13: 2570.5 | O13: 2570.5 | P13: 2570.5 | Q13: =SUM(D13:P13) -> 7711.5 | R13: =Q13-B13 -> 711.5
A14: Sonia Silva | B14: 1589.1 | C14: 3 | N14: 583.5 | O14: 583.5 | P14: 583.5 | Q14: =SUM(D14:P14) -> 1750.5 | R14: =Q14-B14 -> 161.4
A15: Chela Silva | B15: 4000 | C15: 2 | O15: 2151.2 | P15: 2151.2 | Q15: =SUM(D15:P15) -> 4302.4 | R15: =Q15-B15 -> 302.4
A16: Jennifer Nuñez | B16: 3500 | C16: 2 | O16: 1882.3 | P16: 1882.3 | Q16: =SUM(D16:P16) -> 3764.6 | R16: =Q16-B16 -> 264.6
A17: Cledmir Tejada | B17: 1082.5 | C17: 1 | O17: 1136.6 | Q17: =SUM(D17:P17) -> 1136.6 | R17: =Q17-B17 -> 54.1
A18: Cledmir Tejada | B18: 2565.3 | C18: 1 | P18: 2693.6 | Q18: =SUM(D18:P18) -> 2693.6 | R18: =Q18-B18 -> 128.3
A19: Medelein Poma | B19: 1215.3 | C19: 1 | P19: 1276.1 | Q19: =SUM(D19:P19) -> 1276.1 | R19: =Q19-B19 -> 60.8
A20: Marco Gutierres | B20: 2250 | C20: 1 | P20: 2362.5 | Q20: =SUM(D20:P20) -> 2362.5 | R20: =Q20-B20 -> 112.5
A21: Nora Silva | B21: 1395.3 | C21: 1 | P21: 1465.1 | Q21: =SUM(D21:P21) -> 1465.1 | R21: =Q21-B21 -> 69.8
A22: Jhary Bravo | B22: 1500 | C22: 1 | P22: 1575 | Q22: =SUM(D22:P22) -> 1575 | R22: =Q22-B22 -> 75
A23: Kelly Gonzales | B23: 1765.3 | C23: 1 | P23: 1853.6 | Q23: =SUM(D23:P23) -> 1853.6 | R23: =Q23-B23 -> 88.3
A24: Adriana Gutierrez | B24: 765.3 | C24: 1 | P24: 803.6 | Q24: =SUM(D24:P24) -> 803.6 | R24: =Q24-B24 -> 38.3
A25: Chela Silva | B25: 765.3 | C25: 1 | P25: 803.6 | Q25: =SUM(D25:P25) -> 803.6 | R25: =Q25-B25 -> 38.3
A26: Haytza Silva | B26: 765.3 | C26: 1 | P26: 803.6 | Q26: =SUM(D26:P26) -> 803.6 | R26: =Q26-B26 -> 38.3
A27: Sonia Silva | B27: 765.3 | C27: 1 | P27: 803.6 | Q27: =SUM(D27:P27) -> 803.6 | R27: =Q27-B27 -> 38.3
A28: Total | D28: =SUM(D3:D22) -> 0 | E28: =SUM(E3:E22) -> 146.7 | F28: =SUM(F3:F22) -> 370.2 | G28: =SUM(G3:G22) -> 693.4 | H28: =SUM(H3:H22) -> 1312 | I28: =SUM(I3:I22) -> 1798 | J28: =SUM(J3:J22) -> 2368 | K28: =SUM(K3:K22) -> 3130.1 | ... P28: =SUM(P3:P22) -> 20002.3 | Q28: Total de intereses | R28: =SUM(R3:R27) -> 7060.1
Q29: Ganancia por numero | R29: =R28/15 -> 470.67333
A30: Ingresos Extra | D30: Diciembre | E30: Enero | F30: Febrero | G30: Marzo | H30: Abril | I30: Mayo | J30: Junio | K30: Julio | L30: Agosto | M30: Setiembre | N30: Octubre | O30: Noviembre | P30: Diciembre
A31: Estefanny añade un número y se pone al dia | E31: 105
A32: Nora entra al banquito | E32: 105
A33: Adelanto de Cuota de Omar | M33: 2075.3 | Q33: Cada Numero recibe | R33: =1200 + R29 -> 1670.6733
A36: Monto total recaudado | D36: =D28+'Participantes - Banquito'!B15+SUM(D31:D34) -> 1300 | E36: =E28+'Participantes - Banquito'!C15+SUM(E31:E34) -> 1856.7 | F36: =F28+'Participantes - Banquito'!D15+SUM(F31:F34) -> 1870.2 | G36: =G28+'Participantes - Banquito'!E15+SUM(G31:G34) -> 2193.4 | H36: =H28+'Participantes - Banquito'!F15+SUM(H31:H34) -> 2812 | I36: =I28+'Participantes - Banquito'!G15+SUM(I31:I34) -> 3298 | J36: =J28+'Participantes - Banquito'!H15+SUM(J31:J34) -> 3868 | K36: =K28+'Participantes - Banquito'!I15+SUM(K31:K34) -> 4630.1 | ... P36: =P28+'Participantes - Banquito'!N15+SUM(P31:P34) -> 21502.3
A38: Simulador
A39: Monto | C39: 1335.4 | D39: Cuotas | E39: 5 | J39: =O36-SUM(B18:B27) -> 0.2
A40: Monto mensual | C40: =(C39*0.05*(1+0.05)^E39)/(((1+0.05)^E39)-1) -> 308.44375
N41: 2400
B42: Monto total | C42: =C40*E39 -> 1542.2187
B43: Interes | C43: =C42-C39 -> 206.81873

Sheet Participantes - Canastita
A1: Nombre | B1: Diciembre | C1: Enero | D1: Febrero | E1: Marzo | F1: Abril | G1: Mayo | H1: Junio | I1: Julio | J1: Agosto | K1: Setiembre | L1: Octubre | M1: Noviembre | N1: Diciembre
A2: Sonia Silva | B2: 4 | C2: 4 | D2: 4 | E2: 4 | F2: 4 | G2: 4 | H2: 4 | I2: 4 | J2: 4 | K2: 4 | L2: 4 | M2: 4 | N2: 4
A3: Maria Magdalena | B3: 3 | C3: 3 | D3: 3 | E3: 3 | F3: 3 | G3: 3 | H3: 3 | I3: 3 | J3: 3 | K3: 3 | L3: 3 | M3: 3 | N3: 3
A4: Jennifer Nuñez | B4: 2 | C4: 2 | D4: 2 | E4: 2 | F4: 2 | G4: 2 | H4: 2 | I4: 2 | J4: 2 | K4: 2 | L4: 2 | M4: 2 | N4: 2
A5: Domenica Meza | B5: 1 | C5: 1 | D5: 1 | E5: 1 | F5: 1 | G5: 1 | H5: 1 | I5: 1 | J5: 1 | K5: 1 | L5: 1 | M5: 1 | N5: 1
A6: Fabiano Meza | B6: 1 | C6: 1 | D6: 1 | E6: 1 | F6: 1 | G6: 1 | H6: 1 | I6: 1 | J6: 1 | K6: 1 | L6: 1 | M6: 1 | N6: 1
A7: Marco Gutierres | B7: 4 | C7: 4 | D7: 4 | E7: 4 | F7: 4 | G7: 4 | H7: 4 | I7: 4 | J7: 4 | K7: 4 | L7: 4 | M7: 4 | N7: 4
A8: Adriana Gutierres | B8: 3 | C8: 4 | D8: 4 | E8: 4 | F8: 4 | G8: 4 | H8: 4 | I8: 4 | J8: 4 | K8: 4 | L8: 4 | M8: 4 | N8: 4
A9: Marco Jr | B9: 2 | C9: 2 | D9: 2 | E9: 2 | F9: 2 | G9: 2 | H9: 2 | I9: 2 | J9: 2 | K9: 2 | L9: 2 | M9: 2 | N9: 2
A10: Bettina Leguia | B10: 1 | C10: 2 | D10: 2 | E10: 2 | F10: 2 | G10: 2 | H10: 2 | I10: 2 | J10: 2 | K10: 2 | L10: 2 | M10: 2 | N10: 2
A11: Estefanny Silva | B11: 1 | C11: 1 | D11: 1 | E11: 1 | F11: 1 | G11: 1 | H11: 1 | I11: 1 | J11: 1 | K11: 1 | L11: 1 | M11: 1 | N11: 1
A12: Kelly Gonzales | B12: 1 | C12: 1 | D12: 1 | E12: 1 | F12: 1 | G12: 1 | H12: 1 | I12: 1 | J12: 1 | K12: 1 | L12: 1 | M12: 1 | N12: 1
A13: Haytza Silva | B13: 1 | C13: 1 | D13: 1 | E13: 1 | F13: 1 | G13: 1 | H13: 1 | I13: 1 | J13: 1 | K13: 1 | L13: 1 | M13: 1 | N13: 1
... A19: Graciela Silva | B19: 1 | C19: 1 | D19: 1 | E19: 1 | F19: 1 | G19: 1 | H19: 1 | I19: 1 | J19: 1 | K19: 1 | L19: 1 | M19: 1 | N19: 1
A20: Total | B20: =20*(SUM(B2:B19)) -> 600 | C20: =20*(SUM(C2:C19)) -> 640 | D20: =20*(SUM(D2:D19)) -> 640 | E20: =20*(SUM(E2:E19)) -> 640 | F20: =20*(SUM(F2:F19)) -> 640 | G20: =20*(SUM(G2:G19)) -> 640 | H20: =20*(SUM(H2:H19)) -> 640 | I20: =20*(SUM(I2:I19)) -> 640 | ... N20: =20*(SUM(N2:N19)) -> 640

Sheet Flujo de Caja - Canastita
A2: Nombre | B2: Monto Prestado | C2: N° Cuotas | D2: Diciembre | E2: Enero | F2: Febrero | G2: Marzo | H2: Abril | I2: Mayo | J2: Junio | K2: Julio | L2: Agosto | M2: Setiembre | N2: Octubre | O2: Noviembre | P2: Diciembre | Q2: Monto Total Pagado | R2: Intereses Generados
A3: Jennifer Nuñez | B3: 300 | C3: 2 | E3: 165 | F3: 165 | Q3: =SUM(D3:P3) -> 330 | R3: =Q3-B3 -> 30
A4: Maria Magdalena | B4: 300 | C4: 2 | E4: 165 | F4: 165 | Q4: =SUM(D4:P4) -> 330 | R4: =Q4-B4 -> 30
A5: Abran | B5: 100 | C5: 3 | F5: 48.3 | G5: 48.3 | H5: 48.3 | Q5: =SUM(D5:P5) -> 144.9 | R5: =Q5-B5 -> 44.9
A6: Domenica Meza | B6: 400 | C6: 4 | F6: 120 | G6: 120 | H6: 120 | I6: 120 | Q6: =SUM(D6:P6) -> 480 | R6: =Q6-B6 -> 80
A7: Nora Silva | B7: 492 | C7: 10 | F7: 73.8 | G7: 73.8 | H7: 73.8 | I7: 73.8 | J7: 73.8 | K7: 73.8 | L7: 73.8 | M7: 73.8 | N7: 73.8 | O7: 73.8 | Q7: =SUM(D7:P7) -> 738 | R7: =Q7-B7 -> 246
A8: Bettina Leguia | B8: 40 | C8: 1 | F8: 42 | Q8: =SUM(D8:P8) -> 42 | R8: =Q8-B8 -> 2
A9: Geraldine | B9: 313.5 | C9: 3 | G9: 120.2 | H9: 120.2 | I9: 120.2 | Q9: =SUM(D9:P9)+M25 -> 360.6 | R9: =Q9-B9 -> 47.1
A10: Estefanny Silva | B10: 313.6 | C10: 3 | G10: 120.2 | H10: 120.2 | I10: 120.2 | Q10: =SUM(D10:P10) -> 360.6 | R10: =Q10-B10 -> 47
A11: Sharmely Poma | B11: 313.5 | C11: 6 | G11: 67.9 | H11: 67.9 | I11: 67.9 | J11: 67.9 | K11: 67.9 | L11: 67.9 | Q11: =SUM(D11:P11) -> 407.4 | R11: =Q11-B11 -> 93.9
A12: Jennifer Nuñez | B12: 313.5 | C12: 2 | G12: 172.4 | H12: 172.4 | Q12: =SUM(D12:P12) -> 344.8 | R12: =Q12-B12 -> 31.3
A13: Adriana Gutierrez | B13: 521.4 | C13: 2 | H13: 268.8 | I13: 286.8 | Q13: =SUM(D13:P13) -> 555.6 | R13: =Q13-B13 -> 34.2
A14: Daleska | B14: 521.4 | C14: 5 | H14: 130.4 | I14: 130.4 | J14: 130.4 | K14: 130.4 | L14: 130.4 | Q14: =SUM(D14:P14) -> 652 | R14: =Q14-B14 -> 130.6
A15: Haytza Silva | B15: 300 | C15: 3 | H15: 75 | I15: 75 | Q15: =SUM(D15:P15) -> 150 | R15: =Q15-B15 -> -150
A16: Kelly Gonzales | B16: 918.5 | C16: 6 | I16: 199 | J16: 199 | K16: 199 | L16: 199 | M16: 199 | N16: 199 | Q16: =SUM(D16:P16) -> 1194 | R16: =Q16-B16 -> 275.5
A17: Graciela Silva | B17: 918.5 | C17: 3 | I17: 352.1 | J17: 352.1 | K17: 352.1 | Q17: =SUM(D17:P17) -> 1056.3 | R17: =Q17-B17 -> 137.8
A18: Maria Magdalena | B18: 2384.3 | C18: 6 | J18: 516.6 | K18: 516.6 | L18: 516.6 | M18: 516.6 | N18: 516.6 | O18: 516.6 | Q18: =SUM(D18:P18) -> 3099.6 | R18: =Q18-B18 -> 715.3
A19: Jennifer Nuñez | B19: 989.9 | C19: 4 | K19: 297 | L19: 297 | M19: 297 | N19: 297 | Q19: =SUM(D19:P19) -> 1188 | R19: =Q19-B19 -> 198.1
A20: Geraldine | B20: 989.9 | C20: 5 | K20: 247.5 | L20: 247.5 | M20: 247.5 | N20: 247.5 | O20: 247.5 | Q20: =SUM(D20:P20) -> 1237.5 | R20: =Q20-B20 -> 247.6
A21: Maria Magdalena | B21: 2628.6 | C21: 4 | L21: 657.2 | M21: 657.2 | N21: 657.2 | O21: 657.2 | P21: 657.2 | Q21: =SUM(D21:P21) -> 3286 | R21: =Q21-B21 -> 657.4
A22: Sonia Silva | B22: 500 | C22: 4 | M22: 150 | N22: 150 | O22: 150 | P22: 150 | Q22: =SUM(D22:P22) -> 600 | R22: =Q22-B22 -> 100
A23: Sharmely Poma | B23: 1500 | C23: 3 | M23: 575 | N23: 575 | O23: 575 | Q23: =SUM(D23:P23) -> 1725 | R23: =Q23-B23 -> 225
A24: Estefanny Silva | B24: 699 | M24: 209.7 | N24: 209.7 | O24: 209.7 | P24: 209.7 | Q24: =SUM(D24:P24) -> 838.8 | R24: =Q24-B24 -> 139.8
A25: Sonia Silva | B25: 565.8 | C25: 3 | N25: 216.9 | O25: 216.9 | P25: 216.9 | Q25: =SUM(D25:P25) -> 650.7 | R25: =Q25-B25 -> 84.9
A26: Kelly Gonzales | B26: 1500 | C26: 1 | N26: 1575 | Q26: =SUM(D26:P26) -> 1575 | R26: =Q26-B26 -> 75
A27: Haytza Silva | B27: 1500 | C27: 1 | N27: 1575 | Q27: =SUM(D27:P27) -> 1575 | R27: =Q27-B27 -> 75
A28: Geraldyn | B28: 1500 | C28: 2 | O28: 825 | P28: 825 | Q28: =SUM(D28:P28) -> 1650 | R28: =Q28-B28 -> 150
A29: Kelly Gonzales | B29: 1000 | C29: 2 | O29: 550 | P29: 550 | Q29: =SUM(D29:P29) -> 1100 | R29: =Q29-B29 -> 100
A30: Estefanny Silva | B30: 4432.7 | C30: 2 | O30: 2438 | P30: 2438 | Q30: =SUM(D30:P30) -> 4876 | R30: =Q30-B30 -> 443.3
A31: Geraldyn | B31: 800 | C31: 1 | P31: 840 | Q31: =SUM(D31:P31) -> 840 | R31: =Q31-B31 -> 40
A32: Estefanny Silva | B32: 2000 | C32: 1 | P32: 2100 | Q32: =SUM(D32:P32) -> 2100 | R32: =Q32-B32 -> 100
A33: Haytza Silva | B33: 500 | C33: 1 | P33: 525 | Q33: =SUM(D33:P33) -> 525 | R33: =Q33-B33 -> 25
A34: Jennifer Nuñez | B34: 500 | C34: 1 | P34: 525 | Q34: =SUM(D34:P34) -> 525 | R34: =Q34-B34 -> 25
Q35: =SUM(D35:P35) -> 0 | R35: =Q35-B35 -> 0
Q36: =SUM(D36:P36) -> 0 | R36: =Q36-B36 -> 0
Q38: =SUM(D38:P38) -> 0 | R38: =Q38-B38 -> 0
A39: Total | D39: =SUM(D3:D31) -> 0 | E39: =SUM(E3:E31) -> 330 | F39: =SUM(F3:F31) -> 614.1 | G39: =SUM(G3:G31) -> 722.8 | H39: =SUM(H3:H31) -> 1197 | I39: =SUM(I3:I31) -> 1545.4 | J39: =SUM(J3:J31) -> 1339.8 | K39: =SUM(K3:K31) -> 1884.3 | ... P39: =SUM(P3:P31) -> 5886.8 | R39: =SUM(R3:R38) -> 4481.7
A41: Ingresos Extra | D41: Diciembre | E41: Enero | F41: Febrero | G41: Marzo | H41: Abril | I41: Mayo | J41: Junio | K41: Julio | L41: Agosto | M41: Setiembre | N41: Octubre | O41: Noviembre | P41: Diciembre
A42: Adriana añadio un numero | E42: 21
A43: Bettina añadio un numero | E43: 21
...

Sheet Interes Simple
A1: Monto | B1: 313.5 | C1: Cuotas | D1: 6
A4: Monto mensual | B4: =(B1+(B1*0.05*D1))/D1 -> 67.925

Sheet Interes Compuesto
A1: Monto | B1: 2812.1 | C1: Cuotas | D1: 7
A4: Monto mensual | B4: =(B1*0.05*(1+0.05)^D1)/(((1+0.05)^D1)-1) -> 485.98661
